caught io exception
caught arithmetic exception
after the catch block
